Workbook
Name Slicer_Order_Cateogry: #N/A
Name Slicer_Order_status: #N/A
Name Slicer_Order_status1: #N/A
Name Slicer_Payment_Mode: #N/A
Name Slicer_Type_Of_Products: #N/A
Name Slicer_Type_Of_Products1: #N/A
Name Slicer_Type_Of_Products2: #N/A
Name Slicer_Type_Of_Products3: #N/A

Sheet Orders
C1: E-COMMERCE SALES ANALYTICS FOR MONTH OF JANUARY FOR VyaaparX STARTUP COMPANY
A3: Order ID | B3: Order_Date | C3: Customer ID | D3: Product ID | E3: Quantity | F3: Unit_Price | G3: Gross_Sales | H3: Discount | I3: Discount_Amount | J3: Delivery_Charges | K3: Net Sales | L3: Surplus | M3: Customer_Name | N3: Order Cateogry | O3: Type Of Products | P3: City | Q3: Payment_Mode | R3: Order_status
A4: ORD1001 | B4: 45669 | C4: C001 | D4: P001 | E4: 4 | F4: 899 | G4: =F4*E4 -> 3596 | H4: 0.1 | I4: =G4*H4 -> 359.6 | J4: =G4*0.4 -> 1438.4 | K4: =G4+J4-I4 -> 4674.8 | L4: =K4-G4 -> 1078.8 | M4: {=_xlfn.XLOOKUP(Orders!C4,Customers!A5:A204,Customers!G5:'Customers'!G204,"Not Found")} -> Aarav Mehta | N4: =IF(K4<5000,"Micro",IF(K4<10000,"Small",IF(K4<=30000,"Medium",IF(K4<=100000,"Large",IF(K4<=125000,"Industrial","Wholesale"))))) -> Micro | O4: Books & Stationeries | P4: Agartala | Q4: Credit Card | R4: Delivered
A5: ORD1002 | B5: 45669 | C5: C002 | D5: P002 | E5: 5 | F5: 649 | G5: =E5*F5 -> 3245 | H5: 0.02 | I5: =G5*H5 -> 64.9 | J5: =G5*0.4 -> 1298 | K5: =G5+J5-I5 -> 4478.1 | L5: =K5-G5 -> 1233.1 | M5: {=_xlfn.XLOOKUP(Orders!C5,Customers!A6:A205,Customers!G6:'Customers'!G205,"Not Found")} -> Aditi Patel | N5: =IF(K5<5000,"Micro",IF(K5<10000,"Small",IF(K5<=30000,"Medium",IF(K5<=100000,"Large",IF(K5<=125000,"Industrial","Wholesale"))))) -> Micro | O5: Books & Stationeries | P5: Agra | Q5: UPI | R5: Delivered
A6: ORD1003 | B6: 45669 | C6: C003 | D6: P003 | E6: 6 | F6: 125 | G6: =E6*F6 -> 750 | H6: 0 | I6: =G6*H6 -> 0 | J6: =G6*0.4 -> 300 | K6: =G6+J6-I6 -> 1050 | L6: =K6-G6 -> 300 | M6: {=_xlfn.XLOOKUP(Orders!C6,Customers!A7:A206,Customers!G7:'Customers'!G206,"Not Found")} -> Arjun Khanna | N6: =IF(K6<5000,"Micro",IF(K6<10000,"Small",IF(K6<=30000,"Medium",IF(K6<=100000,"Large",IF(K6<=125000,"Industrial","Wholesale"))))) -> Micro | O6: Books & Stationeries | P6: Ahmedabad | Q6: Cash on delivery | R6: Delivered
A7: ORD1004 | B7: 45669 | C7: C004 | D7: P004 | E7: 7 | F7: 199 | G7: =E7*F7 -> 1393 | H7: 0 | I7: =G7*H7 -> 0 | J7: =G7*0.4 -> 557.2 | K7: =G7+J7-I7 -> 1950.2 | L7: =K7-G7 -> 557.2 | M7: {=_xlfn.XLOOKUP(Orders!C7,Customers!A8:A207,Customers!G8:'Customers'!G207,"Not Found")} -> Ananya Khanna | N7: =IF(K7<5000,"Micro",IF(K7<10000,"Small",IF(K7<=30000,"Medium",IF(K7<=100000,"Large",IF(K7<=125000,"Industrial","Wholesale"))))) -> Micro | O7: Books & Stationeries | P7: Aizawl | Q7: Cash on delivery | R7: Delivered
A8: ORD1005 | B8: 45670 | C8: C005 | D8: P005 | E8: 2 | F8: 900 | G8: =E8*F8 -> 1800 | H8: 0.15 | I8: =G8*H8 -> 270 | J8: =G8*0.4 -> 720 | K8: =G8+J8-I8 -> 2250 | L8: =K8-G8 -> 450 | M8: {=_xlfn.XLOOKUP(Orders!C8,Customers!A9:A208,Customers!G9:'Customers'!G208,"Not Found")} -> Aditya Kulkarni | N8: =IF(K8<5000,"Micro",IF(K8<10000,"Small",IF(K8<=30000,"Medium",IF(K8<=100000,"Large",IF(K8<=125000,"Industrial","Wholesale"))))) -> Micro | O8: Cosmetics | P8: Ajmer | Q8: Cash on delivery | R8: Delivered
A9: ORD1006 | B9: 45670 | C9: C006 | D9: P006 | E9: 3 | F9: 1200 | G9: =E9*F9 -> 3600 | H9: 0.15 | I9: =G9*H9 -> 540 | J9: =G9*0.4 -> 1440 | K9: =G9+J9-I9 -> 4500 | L9: =K9-G9 -> 900 | M9: {=_xlfn.XLOOKUP(Orders!C9,Customers!A10:A209,Customers!G10:'Customers'!G209,"Not Found")} -> Ishita Yadav | N9: =IF(K9<5000,"Micro",IF(K9<10000,"Small",IF(K9<=30000,"Medium",IF(K9<=100000,"Large",IF(K9<=125000,"Industrial","Wholesale"))))) -> Micro | O9: Confectionaries | P9: Aligarh | Q9: Cash on delivery | R9: Delivered
A10: ORD1007 | B10: 45670 | C10: C007 | D10: P007 | E10: 4 | F10: 800 | G10: =E10*F10 -> 3200 | H10: 0.15 | I10: =G10*H10 -> 480 | J10: =G10*0.4 -> 1280 | K10: =G10+J10-I10 -> 4000 | L10: =K10-G10 -> 800 | M10: {=_xlfn.XLOOKUP(Orders!C10,Customers!A11:A210,Customers!G11:'Customers'!G210,"Not Found")} -> Kabir Mathur | N10: =IF(K10<5000,"Micro",IF(K10<10000,"Small",IF(K10<=30000,"Medium",IF(K10<=100000,"Large",IF(K10<=125000,"Industrial","Wholesale"))))) -> Micro | O10: Electronics | P10: Amravati | Q10: Cash on delivery | R10: Delivered
A11: ORD1008 | B11: 45670 | C11: C008 | D11: P008 | E11: 5 | F11: 700 | G11: =E11*F11 -> 3500 | H11: 0.15 | I11: =G11*H11 -> 525 | J11: =G11*0.4 -> 1400 | K11: =G11+J11-I11 -> 4375 | L11: =K11-G11 -> 875 | M11: {=_xlfn.XLOOKUP(Orders!C11,Customers!A12:A211,Customers!G12:'Customers'!G211,"Not Found")} -> Meera Gupta | N11: =IF(K11<5000,"Micro",IF(K11<10000,"Small",IF(K11<=30000,"Medium",IF(K11<=100000,"Large",IF(K11<=125000,"Industrial","Wholesale"))))) -> Micro | O11: Books & Stationeries | P11: Amritsar | Q11: Cash on delivery | R11: Delivered
A12: ORD1009 | B12: 45671 | C12: C009 | D12: P009 | E12: 1 | F12: 600 | G12: =E12*F12 -> 600 | H12: 0.15 | I12: =G12*H12 -> 90 | J12: =G12*0.4 -> 240 | K12: =G12+J12-I12 -> 750 | L12: =K12-G12 -> 150 | M12: {=_xlfn.XLOOKUP(Orders!C12,Customers!A13:A212,Customers!G13:'Customers'!G212,"Not Found")} -> Rohan Iyer | N12: =IF(K12<5000,"Micro",IF(K12<10000,"Small",IF(K12<=30000,"Medium",IF(K12<=100000,"Large",IF(K12<=125000,"Industrial","Wholesale"))))) -> Micro | O12: Books & Stationeries | P12: Aurangabad | Q12: Cash on delivery | R12: Delivered
A13: ORD1010 | B13: 45671 | C13: C010 | D13: P010 | E13: 3 | F13: 3000 | G13: =E13*F13 -> 9000 | H13: 0.15 | I13: =G13*H13 -> 1350 | J13: =G13*0.4 -> 3600 | K13: =G13+J13-I13 -> 11250 | L13: =K13-G13 -> 2250 | M13: {=_xlfn.XLOOKUP(Orders!C13,Customers!A14:A213,Customers!G14:'Customers'!G213,"Not Found")} -> Priya Mishra | N13: =IF(K13<5000,"Micro",IF(K13<10000,"Small",IF(K13<=30000,"Medium",IF(K13<=100000,"Large",IF(K13<=125000,"Industrial","Wholesale"))))) -> Medium | O13: Toys | P13: Bangalore | Q13: Cash on delivery | R13: Delivered
A14: ORD1011 | B14: 45671 | C14: C011 | D14: P011 | E14: 5 | F14: 2500 | G14: =E14*F14 -> 12500 | H14: 0.2 | I14: =G14*H14 -> 2500 | J14: =G14*0.4 -> 5000 | K14: =G14+J14-I14 -> 15000 | L14: =K14-G14 -> 2500 | M14: {=_xlfn.XLOOKUP(Orders!C14,Customers!A15:A214,Customers!G15:'Customers'!G214,"Not Found")} -> Rahul Pandey | N14: =IF(K14<5000,"Micro",IF(K14<10000,"Small",IF(K14<=30000,"Medium",IF(K14<=100000,"Large",IF(K14<=125000,"Industrial","Wholesale"))))) -> Medium | O14: Dry Fruits | P14: Bareilly | Q14: Credit Card | R14: Pending
A15: ORD1012 | B15: 45671 | C15: C012 | D15: P012 | E15: 7 | F15: 2300 | G15: =E15*F15 -> 16100 | H15: 0.2 | I15: =G15*H15 -> 3220 | J15: =G15*0.4 -> 6440 | K15: =G15+J15-I15 -> 19320 | L15: =K15-G15 -> 3220 | M15: {=_xlfn.XLOOKUP(Orders!C15,Customers!A16:A215,Customers!G16:'Customers'!G215,"Not Found")} -> Sneha Srivastava | N15: =IF(K15<5000,"Micro",IF(K15<10000,"Small",IF(K15<=30000,"Medium",IF(K15<=100000,"Large",IF(K15<=125000,"Industrial","Wholesale"))))) -> Medium | O15: Home and kitchen | P15: Chandigarh | Q15: Credit Card | R15: Delivered
A16: ORD1013 | B16: 45671 | C16: C013 | D16: P013 | E16: 9 | F16: 2100 | G16: =E16*F16 -> 18900 | H16: 0.2 | I16: =G16*H16 -> 3780 | J16: =G16*0.4 -> 7560 | K16: =G16+J16-I16 -> 22680 | L16: =K16-G16 -> 3780 | M16: {=_xlfn.XLOOKUP(Orders!C16,Customers!A17:A216,Customers!G17:'Customers'!G216,"Not Found")} -> Vihaan Dutta | N16: =IF(K16<5000,"Micro",IF(K16<10000,"Small",IF(K16<=30000,"Medium",IF(K16<=100000,"Large",IF(K16<=125000,"Industrial","Wholesale"))))) -> Medium | O16: Home and kitchen | P16: Chennai | Q16: Credit Card | R16: Pending
... A203: ORD1200 | B203: 45688 | C203: C200 | D203: P200 | E203: 1 | F203: 84000 | G203: =E203*F203 -> 84000 | H203: 0.01 | I203: =G203*H203 -> 840 | J203: =G203*0.4 -> 33600 | K203: =G203+J203-I203 -> 116760 | L203: =K203-G203 -> 32760 | M203: {=_xlfn.XLOOKUP(Orders!C203,Customers!A204:A403,Customers!G204:'Customers'!G403,"Not Found")} -> Aanya Naidu | N203: =IF(K203<5000,"Micro",IF(K203<10000,"Small",IF(K203<=30000,"Medium",IF(K203<=100000,"Large",IF(K203<=125000,"Industrial","Wholesale"))))) -> Industrial | O203: Electronics | P203: Surat | Q203: EMI | R203: Pending
E204: =SUM(E4:E203) -> 1132 | F204: =SUM(F4:F203) -> 5475232 | G204: =SUM(G4:G203) -> 17142340 | I204: =SUM(I4:I203) -> 2666007.2 | J204: =SUM(J4:J203) -> 6856936 | K204: =SUM(K4:K203) -> 21333269
A207: =COUNTA(A4:A203) -> 200
E211: Column1 | F211: Pending Orders | G211: Delivered Orders | H211: EMI | I211: No cost EMI | J211: Credit Card | K211: Cash on delivery | L211: No of orders | N211: UPI | P211: Buy now pay later
E212: Total | F212: =COUNTIF(R4:R203, "pending") -> 139 | G212: =COUNTIF(R4:R203,"delivered") -> 61 | H212: =COUNTIF(Q4:Q203, "EMI ") -> 74 | I212: =COUNTIF(Q4:Q203,"No Cost EMI") -> 7 | J212: =COUNTIF(Q4:Q203, "Credit Card") -> 67 | K212: =COUNTIF(Q4:Q203,"cash on delivery") -> 27 | L212: =COUNTA(A4:A203) -> 200 | N212: =COUNTIF(Q4:Q203,"UPI") -> 17 | P212: =COUNTIF(Q4:Q203,"Buy now pay later") -> 8
E218: Column1 | F218: Net sales | G218: Surplus | H218: Gross Sales
E219: Total | F219: =SUM(K4:K203) -> 21333269 | G219: =SUM(L4:L203) -> 4190928.8 | H219: =SUM(G4:G203) -> 17142340
E220: Average | F220: =AVERAGE(K4:K203) -> 106666.34 | G220: =AVERAGE(L4:L203) -> 20954.644 | H220: =AVERAGE(G4:G203) -> 85711.7
E221: Maximum | F221: =MAX(K4:K203) -> 632500 | G221: =MAX(L4:L203) -> 124500 | H221: =MAX(G4:G203) -> 550000
E222: Minimum | F222: =MIN(K4:K203) -> 560 | G222: =MIN(L4:L203) -> 0 | H222: =MIN(G4:G203) -> 400
H225: =SUM(K4:K203) -> 21333269
D228: ="Pending Orders: "&Orders!F212& CHAR(10) & "Delivered Orders: "&G212 -> Pending Orders: 139 Delivered Orders: 61
C235: Key Business Questions | D235: Answers
C236: Most popular product | D236: refer to powerpoint presentation
C237: which product category generated the highest sales | D237: =_xlfn.XLOOKUP(MAX(E4:E203),E4:E203,O4:O203) -> Electronics
C238: Which customers generated the highest revenue? | D238: =_xlfn.XLOOKUP(MAX(K4:K203),K4:K203,M4:M203) -> Rahul Arora
C239: Which city/state generated the highest sales | D239: =_xlfn.XLOOKUP(MAX(K4:K203),K4:K203,P4:P203) -> Gurugram
C240: what was the average order value | D240: ='monetary analysis '!A15 -> 18845.644
C241: Which payment method was most preferred | D241: ='methods of payment'!A7 -> EMI
C242: Which product category had the highest profit | D242: =_xlfn.XLOOKUP(MAX(L4:L203),L4:L203,O4:O203) -> Electronics
C243: What were the monthly sales ? | D243: =SUM(K4:K203) -> 21333269
C244: Which product category generated the highest sales revenue | D244: =_xlfn.XLOOKUP(MAX(K4:K203),K4:K203,O4:O203) -> Electronics

Sheet Customers
A4: Customer ID | B4: Product ID | C4: Product purchased | D4: type of Product | E4: Quantity | F4: Total amount | G4: Customer_Name | H4: City | I4: State | J4: Age | K4: Customer_Segment | L4: Order Status | M4: Mode Of Payment
A5: C001 | B5: P001 | C5: cartons of reynolds pens | D5: Books & Stationeries | E5: =Orders!E4 -> 4 | F5: =Orders!K4 -> 4674.8 | G5: Aarav Mehta | H5: Agartala | I5: Tripura | J5: 21 | K5: =IF(J5<=25,"student",IF(J5<60,"working adults","Senior Citizen")) -> student | L5: =Orders!R4 -> Delivered | M5: =Orders!Q4 -> Credit Card
A6: C002 | B6: P002 | C6: cartons of Uniball pens | D6: Books & Stationeries | E6: =Orders!E5 -> 5 | F6: =Orders!K5 -> 4478.1 | G6: Aditi Patel | H6: Agra | I6: Uttar Pradesh | J6: 22 | K6: =IF(J6<=25,"student",IF(J6<60,"working adults","Senior Citizen")) -> student | L6: =Orders!R5 -> Delivered | M6: =Orders!Q5 -> UPI
A7: C003 | B7: P003 | C7: cartons of flair easy click ballpoint pens | D7: Books & Stationeries | E7: =Orders!E6 -> 6 | F7: =Orders!K6 -> 1050 | G7: Arjun Khanna | H7: Ahmedabad | I7: Gujrat | J7: 21 | K7: =IF(J7<=25,"student",IF(J7<60,"working adults","Senior Citizen")) -> student | L7: =Orders!R6 -> Delivered | M7: =Orders!Q6 -> Cash on delivery
A8: C004 | B8: P004 | C8: cartons of hauser easy click ballpoint pens | D8: Books & Stationeries | E8: =Orders!E7 -> 7 | F8: =Orders!K7 -> 1950.2 | G8: Ananya Khanna | H8: Aizawl | I8: Mizoram | J8: 19 | K8: =IF(J8<=25,"student",IF(J8<60,"working adults","Senior Citizen")) -> student | L8: =Orders!R7 -> Delivered | M8: =Orders!Q7 -> Cash on delivery
A9: C005 | B9: P005 | C9: packet of Godrej Hair color | D9: Cosmetics | E9: =Orders!E8 -> 2 | F9: =Orders!K8 -> 2250 | G9: Aditya Kulkarni | H9: Ajmer | I9: Rajasthan | J9: 29 | K9: =IF(J9<=25,"student",IF(J9<60,"working adults","Senior Citizen")) -> working adults | L9: =Orders!R8 -> Delivered | M9: =Orders!Q8 -> Cash on delivery
A10: C006 | B10: P006 | C10: Atta Cookies | D10: Confectionaries | E10: =Orders!E9 -> 3 | F10: =Orders!K9 -> 4500 | G10: Ishita Yadav | H10: Aligarh | I10: Uttar Pradesh | J10: 34 | K10: =IF(J10<=25,"student",IF(J10<60,"working adults","Senior Citizen")) -> working adults | L10: =Orders!R9 -> Delivered | M10: =Orders!Q9 -> Cash on delivery
A11: C007 | B11: P007 | C11: Mobile Accessories | D11: Electronics | E11: =Orders!E10 -> 4 | F11: =Orders!K10 -> 4000 | G11: Kabir Mathur | H11: Amravati | I11: Andhra Pradesh | J11: 35 | K11: =IF(J11<=25,"student",IF(J11<60,"working adults","Senior Citizen")) -> working adults | L11: =Orders!R10 -> Delivered | M11: =Orders!Q10 -> Cash on delivery
A12: C008 | B12: P008 | C12: Oswal Sample paper books 12th class | D12: Books & Stationeries | E12: =Orders!E11 -> 5 | F12: =Orders!K11 -> 4375 | G12: Meera Gupta | H12: Amritsar | I12: Punjab | J12: 17 | K12: =IF(J12<=25,"student",IF(J12<60,"working adults","Senior Citizen")) -> student | L12: =Orders!R11 -> Delivered | M12: =Orders!Q11 -> Cash on delivery
A13: C009 | B13: P009 | C13: Oswal Sample paper books 10th class | D13: Books & Stationeries | E13: =Orders!E12 -> 1 | F13: =Orders!K12 -> 750 | G13: Rohan Iyer | H13: Aurangabad | I13: Maharashtra | J13: 16 | K13: =IF(J13<=25,"student",IF(J13<60,"working adults","Senior Citizen")) -> student | L13: =Orders!R12 -> Delivered | M13: =Orders!Q12 -> Cash on delivery
A14: C010 | B14: P010 | C14: Lego set buy 2 get 1 free | D14: Toys | E14: =Orders!E13 -> 3 | F14: =Orders!K13 -> 11250 | G14: Priya Mishra | H14: Bangalore | I14: Karnataka | J14: 17 | K14: =IF(J14<=25,"student",IF(J14<60,"working adults","Senior Citizen")) -> student | L14: =Orders!R13 -> Delivered | M14: =Orders!Q13 -> Cash on delivery
A15: C011 | B15: P011 | C15: packet of Kashmiri Walnuts | D15: Dry Fruits | E15: =Orders!E14 -> 5 | F15: =Orders!K14 -> 15000 | G15: Rahul Pandey | H15: Bareilly | I15: Uttar Pradesh | J15: 27 | K15: =IF(J15<=25,"student",IF(J15<60,"working adults","Senior Citizen")) -> working adults | L15: =Orders!R14 -> Pending | M15: =Orders!Q14 -> Credit Card
A16: C012 | B16: P012 | C16: dryfruit Container Set | D16: Home and kitchen | E16: =Orders!E15 -> 7 | F16: =Orders!K15 -> 19320 | G16: Sneha Srivastava | H16: Chandigarh | I16: Punjab | J16: 32 | K16: =IF(J16<=25,"student",IF(J16<60,"working adults","Senior Citizen")) -> working adults | L16: =Orders!R15 -> Delivered | M16: =Orders!Q15 -> Credit Card
... A204: C200 | B204: P200 | C204: Lenovo Gaming PC | D204: Electronics | E204: =Orders!E203 -> 1 | F204: =Orders!K203 -> 116760 | G204: Aanya Naidu | H204: Surat | I204: Gujrat | J204: 23 | K204: =IF(J204<=25,"student",IF(J204<60,"working adults","Senior Citizen")) -> student | L204: =Orders!R203 -> Pending | M204: =Orders!Q203 -> EMI
E206: =SUM(E5:E204) -> 1132 | G206: =COUNTA(G5:G204) -> 200

Sheet monetary analysis 
A3: Methods Of Payment | B3: Sum of Unit_Price | C3: Count of Quantity
A4: Buy Now Pay later | B4: 102025 | C4: 8
A5: Cash on delivery | B5: 74539 | C5: 27
A6: Credit Card | B6: 1382351 | C6: 67
A7: EMI | B7: 3720244 | C7: 74
A8: No Cost EMI | B8: 169000 | C8: 7
A9: UPI | B9: 27073 | C9: 17
A10: Grand Total | B10: 5475232 | C10: 200
A14: Average order Value
A15: =Table1[[#Totals],[Net Sales]]/Table1[[#Totals],[Quantity]] -> 18845.644

Sheet methods of payment
A3: Methods Of Payment | B3: Count of orders
A4: Buy Now Pay later | B4: 8
A5: Cash on delivery | B5: 27
A6: Credit Card | B6: 67
A7: EMI | B7: 74
A8: No Cost EMI | B8: 7
A9: UPI | B9: 17
A10: Grand Total | B10: 200

Sheet operational analysis of firm
A3: Row Labels | B3: Count of Quantity
A4: Delivered | B4: 61
A5: Pending | B5: 139
A6: Grand Total | B6: 200

Sheet analysis of net sales
A3: Row Labels | B3: Sum of Net Sales
A4: Delivered | B4: 4509185.1
A5: Art and collections | B5: 11340
A6: Beverages | B6: 85167.5
A7: Books & Stationeries | B7: 34778.1
A8: Confectionaries | B8: 4500
A9: Cosmetics | B9: 2250
A10: Drinkware | B10: 48608
A11: Electronics | B11: 2261167.5
A12: Food and Beverages | B12: 5110
A13: Furniture | B13: 51750
A14: Hardware | B14: 60074
A15: Health & Beauty | B15: 6615
... A37: Home and kitchen | B37: 98140
A38: Sports & Fitness | B38: 575900 | F38: =GETPIVOTDATA("Net Sales",$A$3,"Order_status","Pending")/GETPIVOTDATA("Net Sales",$A$3)*100 -> 78.863131
A39: Grand Total | B39: 21333269

Sheet Type of orders
A3: Row Labels | B3: Sum of Surplus
A4: Pending | B4: 3382317.7
A5: Industrial | B5: 242104
A6: Large | B6: 758664.7
A7: Medium | B7: 86865
A8: Micro | B8: 3720
A9: Small | B9: 14976.8
A10: Wholesale | B10: 2275987.2
A11: Grand Total | B11: 3382317.7

Sheet Orders analysis
A3: Row Labels | B3: Sum of Surplus
A4: Apparel | B4: 4620
A5: Pending | B5: 4620
A6: Art and collections | B6: 879467
A7: Delivered | B7: 3240
A8: Pending | B8: 876227
A9: Automotive | B9: 113400
A10: Pending | B10: 113400
A11: Beverages | B11: 35597.5
A12: Delivered | B12: 15417.5
A13: Pending | B13: 20180
A14: Books & Stationeries | B14: 21909.1
A15: Delivered | B15: 9194.1
... A59: Grand Total | B59: 4190928.8

Sheet Logistical Analysis of orders
A3: Row Labels | B3: Sum of Net Sales
A4: Delivered | B4: 4509185.1
A5: Art and collections | B5: 11340
A6: Beverages | B6: 85167.5
A7: Books & Stationeries | B7: 34778.1
A8: Confectionaries | B8: 4500
A9: Cosmetics | B9: 2250
A10: Drinkware | B10: 48608
A11: Electronics | B11: 2261167.5
A12: Food and Beverages | B12: 5110
A13: Furniture | B13: 51750
A14: Hardware | B14: 60074
A15: Health & Beauty | B15: 6615
... A39: Grand Total | B39: 21333269

Sheet Share of each type of customer
A3: Row Labels | B3: Sum of Total amount
A4: Senior Citizen | B4: 581820
A5: student | B5: 2983911.8
A6: working adults | B6: 17767537
A7: Grand Total | B7: 21333269

Sheet Number of orders per state
A3: Row Labels | B3: Count of Customer ID
A4: Andhra Pradesh | B4: 7
A5: Bihar | B5: 1
A6: Delhi | B6: 31
A7: Gujrat | B7: 7
A8: Haryana | B8: 71
A9: Himachal Pradesh | B9: 1
A10: Jammu & Kashmir | B10: 3
A11: Karnataka | B11: 5
A12: Kerala | B12: 2
A13: Maharashtra | B13: 12
A14: Mizoram | B14: 1
A15: Punjab | B15: 4
... A22: Grand Total | B22: 200

Sheet Share of each age group
A3: Row Labels | B3: Sum of Total amount | C3: Count of Quantity
A4: Senior Citizen | B4: 581820 | C4: 4
A5: Buy Now Pay later | B5: 201600 | C5: 1
A6: Haryana | B6: 201600 | C6: 1
A7: Credit Card | B7: 126020 | C7: 2
A8: Gujrat | B8: 31250 | C8: 1
A9: Uttar Pradesh | B9: 94770 | C9: 1
A10: EMI | B10: 254200 | C10: 1
A11: Jammu & Kashmir | B11: 254200 | C11: 1
A12: student | B12: 2983911.8 | C12: 48
A13: Cash on delivery | B13: 145765.2 | C13: 12
A14: Bihar | B14: 4200 | C14: 1
A15: Gujrat | B15: 1050 | C15: 1
... A94: Grand Total | B94: 21333269 | C94: 200

Sheet Share of each type of Product
A3: Row Labels | B3: Count of Quantity | C3: Sum of Total amount
A4: Apparel | B4: 1 | C4: 27720
A5: Art and collections | B5: 33 | C5: 4756657
A6: Automotive | B6: 3 | C6: 465400
A7: Beverages | B7: 8 | C7: 190147.5
A8: Books & Stationeries | B8: 13 | C8: 80343.1
A9: Confectionaries | B9: 1 | C9: 4500
A10: Cosmetics | B10: 2 | C10: 36750
A11: Drinkware | B11: 1 | C11: 48608
A12: Dry Fruits | B12: 2 | C12: 17310
A13: Electronics | B13: 80 | C13: 9820809.2
A14: Fashion & Acessories | B14: 5 | C14: 601625
A15: Food and Beverages | B15: 3 | C15: 99880
... A26: Grand Total | B26: 200 | C26: 21333269
A33: Methods Of Payment | B33: Sum of Net Sales | C33: Sum of Surplus | D33: Count of Quantity
A34: Apparel | B34: 27720 | C34: 4620 | D34: 1
A35: Art and collections | B35: 4756657 | C35: 879467 | D35: 33
A36: Automotive | B36: 465400 | C36: 113400 | D36: 3
A37: Beverages | B37: 190147.5 | C37: 35597.5 | D37: 8
A38: Books & Stationeries | B38: 80343.1 | C38: 21909.1 | D38: 13
A39: Confectionaries | B39: 4500 | C39: 900 | D39: 1
A40: Cosmetics | B40: 36750 | C40: 4950 | D40: 2
A41: Drinkware | B41: 48608 | C41: 9408 | D41: 1
A42: Dry Fruits | B42: 17310 | C42: 3160 | D42: 2
A43: Electronics | B43: 9820809.2 | C43: 1926843.2 | D43: 80
A44: Fashion & Acessories | B44: 601625 | C44: 142925 | D44: 5
A45: Food and Beverages | B45: 99880 | C45: 23330 | D45: 3
... A56: Grand Total | B56: 21333269 | C56: 4190928.8 | D56: 200
A209: Row Labels | B209: Count of Quantity
A210: Apparel | B210: 1
A211: Art and collections | B211: 33
A212: Automotive | B212: 3
A213: Beverages | B213: 8
A214: Books & Stationeries | B214: 13
A215: Confectionaries | B215: 1
A216: Cosmetics | B216: 2
A217: Drinkware | B217: 1
A218: Dry Fruits | B218: 2
A219: Electronics | B219: 80
A220: Fashion & Acessories | B220: 5
...

Sheet Dashboard for ecommerce firm
